sample_market_data.csv
timestamp,symbol,side,price,volume
1000000000,AAPL,BID,150.25,100
1000000100,AAPL,BID,150.24,200
1000000200,AAPL,BID,150.20,150
1000000300,AAPL,ASK,150.27,100
1000000400,AAPL,ASK,150.28,150
1000000500,AAPL,ASK,150.30,200
1000000600,AAPL,BID,150.26,50
